Workbook

Sheet Read me
A1: CarbonKeel — calculation check
A3: What this is | B3: Every figure CarbonKeel shows, worked out again here with ordinary Excel formulas, one step per row, so you can follow the process and check the output yourself. Change any yellow input and every result updates.
A5: How to check | B5: 1. Read a regulation tab top to bottom: inputs, each step, the result. 2. Open the Cross-check tab: it compares each workbook result with the figure CarbonKeel's engine produced, and shows PASS or FAIL. 3. To check another ship, copy its figures from the Verifier view on carbonkeel.com into the Ship check tab.
A7: Colour code | B7: Blue text on yellow = an input you may change. Black = a formula. Green = a value brought in from another tab. Green fill = the main result of a section.
A9: The process | B9: 1. Data: the ship's verified emissions from the EMSA THETIS-MRV public register (or your own fuel figures). 2. Scope: split the emissions by where they happened (between EU ports, into or out of the EU, at berth, UK domestic). 3. Rules: apply each regulation's own share, gases and factors. 4. Price: multiply by the allowance or penalty price. 5. Bill: add EU ETS, UK ETS and FuelEU; show the IMO Net-Zero Framework as a scenario.
A11: Tabs | B11: Assumptions — the prices you can change. Rule tables — every regulatory number used, with its source. EU ETS — the allowance bill (worked example: PETER OLDENDORFF from the register, and a simple ship). FuelEU — fuel intensity, compliance balance, penalty and pooling cost. CII — the A to E rating and how it tightens to 2030. CII G5 — the corrections IMO allows (example: refrigerated containers). EEXI — the design check. Own data bill — your own fuel split by voyage type, with UK ETS. Charter split — who pays what under a time charter. What-if — how speed and biofuel change fuel use. IMO NZF — the Net-Zero Framework scenario (not adopted). Ship check — enter any ship's register figures. Cross-check — workbook against engine, PASS or FAIL.
A13: Limits | B13: Public-register figures are estimates: the register publishes a fuel total but not the fuel types, so the mix is inferred from CO2 per tonne of fuel; it does not publish the deadweight. Allowance and pool prices are assumptions. Not legal or investment advice.
A15: Prepared | B15: 17 October 2026, from CarbonKeel calculation engines v0.3 and the EMSA THETIS-MRV 2025 report, version 6.

Sheet Assumptions
A1: Assumptions you can change
A2: Market prices are inputs, not regulatory facts. CarbonKeel uses these defaults; change them here and every tab updates.
A5: Prices
A6: Step | B6: Value | C6: Unit | D6: How it is worked out | E6: Source
A7: EU allowance (EUA) price | B7: 85 | C7: € per tonne | D7: Used for every EU ETS cost. | E7: Assumption near the September 2026 market average (€85.6/t, Carbon Pulse via IndexBox).
A8: UK allowance (UKA) price | B8: 40 | C8: £ per tonne | D8: Used for every UK ETS cost. | E8: Indicative; no current published level found.
A9: Euros per pound | B9: 1.15 | C9: € per £ | D9: Converts the UK ETS cost to euros for the total. | E9: Assumption.
A10: FuelEU pool price | B10: 110 | C10: € per tCO2e | D10: Cost of buying a deficit from a pool instead of paying the penalty. | E10: Mid-2026 market: OceanScore index €118.90 (Aug 2026), BetterSea trades €106.52 (Jul 2026). Negotiated; no official price.
A11: Consecutive years with a FuelEU penalty, including this one | B11: 1 | C11: years | D11: n in the Article 23(2) multiplier. | E11: Your own record; the public data cannot show it.

Sheet Rule tables
A1: Regulatory numbers
A2: Every factor the calculations use, with where it comes from. These are fixed by law; change them only if the regulation changes.
A5: Carbon factors (tonnes CO2 per tonne of fuel)
A6: Step | B6: Value | C6: Unit | D6: How it is worked out | E6: Source
A7: Heavy fuel oil (HFO) | B7: 3.114 | C7: t CO2 / t | E7: IMO 2018 DCS guidelines / MEPC.352(78) G1; Regulation (EU) 2015/757 Annex I.
A8: Light fuel oil (VLSFO/LFO) | B8: 3.151 | C8: t CO2 / t | E8: IMO 2018 DCS guidelines / MEPC.352(78) G1; Regulation (EU) 2015/757 Annex I.
A9: Marine gas oil (MDO/MGO) | B9: 3.206 | C9: t CO2 / t | E9: IMO 2018 DCS guidelines / MEPC.352(78) G1; Regulation (EU) 2015/757 Annex I.
A10: LNG | B10: 2.75 | C10: t CO2 / t | E10: IMO 2018 DCS guidelines / MEPC.352(78) G1; Regulation (EU) 2015/757 Annex I.
A11: Methanol | B11: 1.375 | C11: t CO2 / t | E11: IMO 2018 DCS guidelines / MEPC.352(78) G1; Regulation (EU) 2015/757 Annex I.
A13: Methane and nitrous oxide (EU and UK ETS)
A14: Step | B14: Value | C14: Unit | D14: How it is worked out | E14: Source
A15: Methane emission factor, liquid fuels | B15: 5e-05 | C15: t CH4 / t fuel | E15: Regulation (EU) 2015/757 Annex I Part A.
A16: Nitrous oxide emission factor, liquid fuels | B16: 0.00018 | C16: t N2O / t fuel | E16: Regulation (EU) 2015/757 Annex I Part A.
A17: Global warming potential, methane | B17: 28 | E17: Delegated Regulation (EU) 2020/1044 (IPCC AR5); UK Order Table C1.
A18: Global warming potential, nitrous oxide | B18: 265 | E18: Same.
A19: First year methane and N2O count in the EU ETS | B19: 2026 | E19: Directive 2003/87/EC Annex I.
A21: EU ETS share of emissions surrendered (phase-in)
A22: Step | B22: Value | C22: Unit | D22: How it is worked out | E22: Source
A23: 2023 | B23: 0 | C23: share | D23: Emissions year 2023 | E23: Directive 2003/87/EC Art. 3gb (no obligation before 2024).
A24: 2024 | B24: 0.4 | C24: share | D24: Emissions year 2024 | E24: Directive 2003/87/EC Art. 3gb (no obligation before 2024).
A25: 2025 | B25: 0.7 | C25: share | D25: Emissions year 2025 | E25: Directive 2003/87/EC Art. 3gb (no obligation before 2024).
A26: 2026 | B26: 1 | C26: share | D26: Emissions year 2026 | E26: Directive 2003/87/EC Art. 3gb (no obligation before 2024).
A27: 2027 | B27: 1 | C27: share | D27: Emissions year 2027 | E27: Directive 2003/87/EC Art. 3gb (no obligation before 2024).
A28: 2028 | B28: 1 | C28: share | D28: Emissions year 2028 | E28: Directive 2003/87/EC Art. 3gb (no obligation before 2024).
A29: 2029 | B29: 1 | C29: share | D29: Emissions year 2029 | E29: Directive 2003/87/EC Art. 3gb (no obligation before 2024).
A30: 2030 | B30: 1 | C30: share | D30: Emissions year 2030 | E30: Directive 2003/87/EC Art. 3gb (no obligation before 2024).
A32: EU ETS scope shares
A33: Step | B33: Value | C33: Unit | D33: How it is worked out | E33: Source
A34: Voyages between EU/EEA ports | B34: 1 | E34: Directive 2003/87/EC Art. 3ga.
A35: Voyages into or out of the EU/EEA | B35: 0.5 | E35: Same.
A36: At berth in EU/EEA ports | B36: 1 | E36: Same.
A37: UK ETS: Great Britain to Northern Ireland | B37: 0.5 | E37: SI 2026/392 Sch. 2A para 15.
A39: FuelEU Maritime
A40: Step | B40: Value | C40: Unit | D40: How it is worked out | E40: Source
A41: Reference intensity (2020 baseline) | B41: 91.16 | C41: gCO2e/MJ | E41: Regulation (EU) 2023/1805 Art. 4(2).
A42: 2025 | B42: 0.02 | C42: reduction | D42: Reduction below the baseline for 2025 (2% for 2025-2029, 6% from 2030, 14.5% from 2035). | E42: Regulation (EU) 2023/1805 Art. 4(2).
A43: 2026 | B43: 0.02 | C43: reduction | D43: Reduction below the baseline for 2026 (2% for 2025-2029, 6% from 2030, 14.5% from 2035). | E43: Regulation (EU) 2023/1805 Art. 4(2).
A44: 2027 | B44: 0.02 | C44: reduction | D44: Reduction below the baseline for 2027 (2% for 2025-2029, 6% from 2030, 14.5% from 2035). | E44: Regulation (EU) 2023/1805 Art. 4(2).
A45: 2028 | B45: 0.02 | C45: reduction | D45: Reduction below the baseline for 2028 (2% for 2025-2029, 6% from 2030, 14.5% from 2035). | E45: Regulation (EU) 2023/1805 Art. 4(2).
A46: 2029 | B46: 0.02 | C46: reduction | D46: Reduction below the baseline for 2029 (2% for 2025-2029, 6% from 2030, 14.5% from 2035). | E46: Regulation (EU) 2023/1805 Art. 4(2).
...

Sheet EU ETS
A1: EU ETS — the allowance bill
A2: Part A rebuilds a real ship's bill from the public register, exactly as carbonkeel.com does. Part B is a simple ship you can recompute on a calculator.
A5: Part A — PETER OLDENDORFF (IMO 9464663), 2025, from the EMSA register
A6: Step | B6: Value | C6: Unit | D6: How it is worked out | E6: Source
A7: Emissions year | B7: 2025 | E7: Register reporting period.
A8: CO2 on voyages between EU/EEA ports | B8: 602.76325 | C8: t | E8: EMSA THETIS-MRV 2025 v6.
A9: CO2 on voyages leaving an EU/EEA port | B9: 5346.6826 | C9: t | E9: Same.
A10: CO2 on voyages arriving at an EU/EEA port | B10: 7493.6838 | C10: t | E10: Same.
A11: CO2 at berth in EU/EEA ports | B11: 386.02269 | C11: t | E11: Same.
A12: ETS-scope CO2 reported by the ship's verifier | B12: 7408.9691 | C12: t | E12: Same ('CO2 emissions to be reported under Directive 2003/87/EC').
A13: Counted: between EU ports × 100% | B13: =$B$8*'Rule tables'!$B$34 -> 602.76325 | C13: t | D13: Directive Art. 3ga: full share.
A14: Counted: leaving and arriving × 50% | B14: =($B$9+$B$10)*'Rule tables'!$B$35 -> 6420.1832 | C14: t | D14: Half of voyages with one end in the EU.
A15: Counted: at berth × 100% | B15: =$B$11*'Rule tables'!$B$36 -> 386.02269 | C15: t | D15: Full share in port.
A16: Our rebuild of ETS-scope CO2 | B16: =$B$13+$B$14+$B$15 -> 7408.9691 | C16: t | D16: Sum of the three counted parts.
A17: Calibration: verifier figure ÷ our rebuild | B17: =IF($B$16=0,0,$B$12/$B$16) -> 1 | D17: 1.000 means our rebuild matches the verifier exactly.
A18: ETS-scope CO2e the bill uses | B18: =$B$16*$B$17 -> 7408.9691 | C18: t | D18: Always the verifier's own figure when the register has one. 2025 counts CO2 only.
A19: Share surrendered for this year | B19: =INDEX('Rule tables'!$B$23:$B$30,MATCH($B$7,'Rule tables'!$A$23:$A$30,0)) -> 0.7 | D19: Looked up in Rule tables: 70% for 2025.
A20: EU allowances due | B20: =$B$18*$B$19 -> 5186.2784 | C20: EUAs | D20: CO2e × share surrendered.
A21: EU ETS cost | B21: =$B$20*Assumptions!$B$7 -> 440833.66 | C21: € | D21: Allowances × EUA price (Assumptions).
A22: Same emissions on the 2026 rules (100%) | B22: =$B$18*'Rule tables'!$B$26*Assumptions!$B$7 -> 629762.38 | C22: € | D22: What the identical year would cost from 2026.
A24: Part B — simple ship: 3,000 t HFO, all between EU ports, 2026
A25: Step | B25: Value | C25: Unit | D25: How it is worked out | E25: Source
A26: Emissions year | B26: 2026 | E26: Example.
A27: HFO burned | B27: 3000 | C27: t | E27: Example.
A28: CO2 | B28: =$B$27*'Rule tables'!$B$7 -> 9342 | C28: t | D28: Fuel × 3.114.
A29: Methane as CO2e | B29: =IF($B$26>='Rule tables'!$B$19,$B$27*'Rule tables'!$B$15*'Rule tables'!$B$17,0) -> 4.2 | C29: t CO2e | D29: Fuel × 0.00005 × 28, from 2026.
A30: Nitrous oxide as CO2e | B30: =IF($B$26>='Rule tables'!$B$19,$B$27*'Rule tables'!$B$16*'Rule tables'!$B$18,0) -> 143.1 | C30: t CO2e | D30: Fuel × 0.00018 × 265, from 2026.
A31: CO2e in scope | B31: =($B$28+$B$29+$B$30)*'Rule tables'!$B$34 -> 9489.3 | C31: t CO2e | D31: All of it is between EU ports, so 100%.
A32: Share surrendered | B32: =INDEX('Rule tables'!$B$23:$B$30,MATCH($B$26,'Rule tables'!$A$23:$A$30,0)) -> 1
A33: EU allowances due | B33: =$B$31*$B$32 -> 9489.3 | C33: EUAs
A34: EU ETS cost | B34: =$B$33*Assumptions!$B$7 -> 806590.5 | C34: €
A35: Surrender by 30 September of the following year (Directive Art. 12(3)). Unsurrendered allowances: €100 per tCO2e penalty and the allowances are still owed (Art. 16(3)). Exceptions to 2030: ice class IA/IA Super 5% fewer allowances; island, outermost-region and public-service derogations (Art. 12(3-b) to (3-e)).

Sheet FuelEU
A1: FuelEU Maritime — intensity, balance, penalty and pooling
A2: FuelEU compares the well-to-wake greenhouse-gas intensity of the energy used with a falling limit. A shortfall is a penalty, or can be bought from a pool.
A5: Part A — simple ship: 3,000 t HFO, all between EU ports, 2026
A6: Step | B6: Value | C6: Unit | D6: How it is worked out | E6: Source
A7: Year | B7: 2026
A8: Total CO2 in the year | B8: ='Rule tables'!$B$7*3000 -> 9342 | C8: t | E8: Example.
A9: Total fuel in the year | B9: 3000 | C9: t | E9: Example.
A10: CO2 per tonne of fuel | B10: =$B$8/$B$9 -> 3.114 | C10: t CO2 / t | D10: 3.114 = heavy fuel oil, 3.206 = gas oil; in between = a blend of the two.
A11: Gas oil share of the fuel, by mass | B11: =MAX(0,MIN(1,($B$10-'Rule tables'!$B$7)/('Rule tables'!$B$9-'Rule tables'!$B$7))) -> 0 | D11: (ratio − 3.114) ÷ (3.206 − 3.114). The rest is heavy fuel oil.
A12: CO2 counted for FuelEU | B12: =$B$8*'Rule tables'!$B$34 -> 9342 | C12: t | D12: All between EU ports, so all of it. | E12: Regulation (EU) 2023/1805 Art. 2: same 100% / 50% / 100% shares.
A13: Fuel burned in scope | B13: =$B$12/$B$10 -> 3000 | C13: t | D13: Counted CO2 ÷ the ship's own CO2 per tonne.
A14: of which heavy fuel oil | B14: =$B$13*(1-$B$11) -> 3000 | C14: t
A15: of which gas oil | B15: =$B$13*$B$11 -> 0 | C15: t
A16: Energy used in scope | B16: =$B$14*'Rule tables'!$B$49+$B$15*'Rule tables'!$B$51 -> 121500000 | C16: MJ | D16: Tonnes × lower calorific value: 40,500 MJ/t HFO, 42,700 MJ/t gas oil. | E16: Annex II.
A17: Greenhouse gas, well to wake | B17: =$B$14*'Rule tables'!$B$49*'Rule tables'!$B$50+$B$15*'Rule tables'!$B$51*'Rule tables'!$B$52 -> 11146410000 | C17: g CO2e | D17: Energy × 91.74 (HFO) or 90.77 (gas oil) gCO2e/MJ. | E17: Annex II.
A18: GHG intensity attained | B18: =$B$17/$B$16 -> 91.74 | C18: gCO2e/MJ | D18: Greenhouse gas ÷ energy.
A19: Reduction for the year | B19: =INDEX('Rule tables'!$B$42:$B$48,MATCH($B$7,'Rule tables'!$A$42:$A$48,0)) -> 0.02
A20: Target intensity | B20: ='Rule tables'!$B$41*(1-$B$19) -> 89.3368 | C20: gCO2e/MJ | D20: 91.16 × (1 − 2%) = 89.3368 for 2025-2029.
A21: Compliance balance | B21: =($B$20-$B$18)*$B$16 -> -2.919888e+08 | C21: g CO2e | D21: (target − attained) × energy. Negative = shortfall. | E21: Annex IV Part A.
A22: Compliance balance | B22: =$B$21/1000000 -> -291.9888 | C22: t CO2e
A23: Statutory penalty per tonne of shortfall | B23: =1000000/($B$18*'Rule tables'!$B$54)*'Rule tables'!$B$53 -> 638.07047 | C23: € per tCO2e | D23: 10^6 ÷ (intensity × 41,000) × €2,400.
A24: Repeat-deficit multiplier | B24: =1+(Assumptions!$B$11-1)/10 -> 1 | C24: × | D24: 1 + (n − 1)/10 (Assumptions: n). | E24: Regulation (EU) 2023/1805 Art. 23(2).
A25: FuelEU penalty if paid | B25: =IF($B$21<0,ABS($B$21)/($B$18*'Rule tables'!$B$54)*'Rule tables'!$B$53*$B$24,0) -> 186309.43 | C25: € | D25: |balance| ÷ (intensity × 41,000) × €2,400 × multiplier. | E25: Annex IV Part B.
A26: Cost if the shortfall is bought from a pool | B26: =IF($B$22<0,ABS($B$22)*Assumptions!$B$10,0) -> 32118.768 | C26: € | D26: Shortfall tonnes × pool price (Assumptions). | E26: Art. 21 (pooling).
A27: Saving from pooling | B27: =$B$25-$B$26 -> 154190.66 | C27: €
A29: Part B — PETER OLDENDORFF, 2025, from the register
A30: Step | B30: Value | C30: Unit | D30: How it is worked out | E30: Source
A31: Year | B31: 2025
A32: Total CO2 in the year | B32: ='EU ETS'!$B$8+'EU ETS'!$B$9+'EU ETS'!$B$10+'EU ETS'!$B$11 -> 13829.152 | C32: t | E32: EMSA THETIS-MRV 2025 v6.
A33: Total fuel in the year | B33: 4426.558 | C33: t | E33: EMSA THETIS-MRV 2025 v6.
A34: CO2 per tonne of fuel | B34: =$B$32/$B$33 -> 3.1241322 | C34: t CO2 / t | D34: 3.114 = heavy fuel oil, 3.206 = gas oil; in between = a blend of the two.
A35: Gas oil share of the fuel, by mass | B35: =MAX(0,MIN(1,($B$34-'Rule tables'!$B$7)/('Rule tables'!$B$9-'Rule tables'!$B$7))) -> 0.1101325 | D35: (ratio − 3.114) ÷ (3.206 − 3.114). The rest is heavy fuel oil.
A36: CO2 counted for FuelEU | B36: ='EU ETS'!$B$8*'Rule tables'!$B$34+('EU ETS'!$B$9+'EU ETS'!$B$10)*'Rule tables'!$B$35+'EU ETS'!$B$11*'Rule tables'!$B$36 -> 7408.9691 | C36: t | D36: Register scope split (EU ETS tab) with the 100% / 50% / 100% shares. | E36: Regulation (EU) 2023/1805 Art. 2: same 100% / 50% / 100% shares.
A37: Fuel burned in scope | B37: =$B$36/$B$34 -> 2371.5287 | C37: t | D37: Counted CO2 ÷ the ship's own CO2 per tonne.
A38: of which heavy fuel oil | B38: =$B$37*(1-$B$35) -> 2110.3463 | C38: t
A39: of which gas oil | B39: =$B$37*$B$35 -> 261.18239 | C39: t
A40: Energy used in scope | B40: =$B$38*'Rule tables'!$B$49+$B$39*'Rule tables'!$B$51 -> 96621513 | C40: MJ | D40: Tonnes × lower calorific value: 40,500 MJ/t HFO, 42,700 MJ/t gas oil. | E40: Annex II.
A41: Greenhouse gas, well to wake | B41: =$B$38*'Rule tables'!$B$49*'Rule tables'!$B$50+$B$39*'Rule tables'!$B$51*'Rule tables'!$B$52 -> 8.8532397e+09 | C41: g CO2e | D41: Energy × 91.74 (HFO) or 90.77 (gas oil) gCO2e/MJ. | E41: Annex II.
A42: GHG intensity attained | B42: =$B$41/$B$40 -> 91.628038 | C42: gCO2e/MJ | D42: Greenhouse gas ÷ energy.
A43: Reduction for the year | B43: =INDEX('Rule tables'!$B$42:$B$48,MATCH($B$31,'Rule tables'!$A$42:$A$48,0)) -> 0.02
...

Sheet COOL MAGNUS
A1: COOL MAGNUS (IMO 9167801) — every step
A2: Refrigerated cargo carrier, Wallem Shipmanagement, 2025 emissions, from the EMSA register. The FuelEU shortfall, the penalty, the pooling cost and the EU ETS bill, worked out line by line.
A5: 1. What the register publishes
A6: Step | B6: Value | C6: Unit | D6: How it is worked out | E6: Source
A7: Total CO2 in 2025 | B7: 742.90394 | C7: t | E7: EMSA THETIS-MRV 2025 v6.
A8: Total fuel in 2025 | B8: 231.723 | C8: t | E8: Same.
A9: CO2 on voyages between EU/EEA ports | B9: 0 | C9: t | E9: Same.
A10: CO2 on voyages leaving an EU/EEA port | B10: 38.472 | C10: t | E10: Same.
A11: CO2 on voyages arriving at an EU/EEA port | B11: 697.48133 | C11: t | E11: Same.
A12: CO2 at berth in EU/EEA ports | B12: 6.95061 | C12: t | E12: Same.
A13: ETS-scope CO2 reported by the verifier | B13: 374.92728 | C13: t | E13: Same.
A14: Distance sailed | B14: 1906.7887 | C14: nm | D14: Total CO2 ÷ the published CO2 per nautical mile. | E14: Same.
A16: 2. Which fuel it burned
A17: Step | B17: Value | C17: Unit | D17: How it is worked out | E17: Source
A18: CO2 per tonne of fuel | B18: =$B$7/$B$8 -> 3.206 | C18: t CO2 / t | D18: 742.904 ÷ 231.723 = 3.206: exactly the factor for gas oil (MDO/MGO).
A19: Gas oil share | B19: =MAX(0,MIN(1,($B$18-'Rule tables'!$B$7)/('Rule tables'!$B$9-'Rule tables'!$B$7))) -> 1 | D19: 100%: the ship burned gas oil only.
A21: 3. How much of it FuelEU and the EU ETS count
A22: Step | B22: Value | C22: Unit | D22: How it is worked out | E22: Source
A23: Between EU ports × 100% | B23: =$B$9*'Rule tables'!$B$34 -> 0 | C23: t CO2 | E23: Directive Art. 3ga; FuelEU Art. 2.
A24: Leaving and arriving × 50% | B24: =($B$10+$B$11)*'Rule tables'!$B$35 -> 367.97666 | C24: t CO2 | D24: 38.472 + 697.481 = 735.953 t, half of it counts.
A25: At berth × 100% | B25: =$B$12*'Rule tables'!$B$36 -> 6.95061 | C25: t CO2
A26: CO2 in scope | B26: =$B$23+$B$24+$B$25 -> 374.92727 | C26: t CO2 | D26: Matches the verifier's 374.93 t.
A28: 4. FuelEU: energy and intensity
A29: Step | B29: Value | C29: Unit | D29: How it is worked out | E29: Source
A30: Gas oil burned in scope | B30: =$B$26/$B$18 -> 116.9455 | C30: t | D30: CO2 in scope ÷ 3.206.
A31: Energy in scope | B31: =$B$30*'Rule tables'!$B$51 -> 4993572.9 | C31: MJ | D31: × 42,700 MJ per tonne. | E31: Annex II.
A32: GHG intensity attained | B32: ='Rule tables'!$B$52 -> 90.77 | C32: gCO2e/MJ | D32: Gas oil's well-to-wake default: 90.77. | E32: Annex II.
A33: FuelEU limit for 2025 | B33: ='Rule tables'!$B$41*(1-'Rule tables'!$B$42) -> 89.3368 | C33: gCO2e/MJ | D33: 91.16 × 0.98 = 89.3368. | E33: Art. 4(2).
A34: Above the limit by | B34: =$B$32-$B$33 -> 1.4332 | C34: gCO2e/MJ
A36: 5. FuelEU: shortfall, penalty and pooling
A37: Step | B37: Value | C37: Unit | D37: How it is worked out | E37: Source
A38: Compliance balance (shortfall) | B38: =-($B$34)*$B$31/1000000 -> -7.1567886 | C38: t CO2e | D38: − gap × energy ÷ 10^6. | E38: Annex IV Part A.
A39: Penalty per tonne of shortfall | B39: =1000000/($B$32*'Rule tables'!$B$54)*'Rule tables'!$B$53 -> 644.88912 | C39: € per tCO2e | E39: Annex IV Part B.
A40: FuelEU penalty if paid | B40: =IF($B$38<0,ABS($B$38)*$B$39*(1+(Assumptions!$B$11-1)/10),0) -> 4615.3351 | C40: €
A41: If bought from a pool instead | B41: =IF($B$38<0,ABS($B$38)*Assumptions!$B$10,0) -> 787.24675 | C41: € | D41: Pool price on Assumptions.
A43: 6. EU ETS
A44: Step | B44: Value | C44: Unit | D44: How it is worked out | E44: Source
A45: Verifier ÷ our rebuild | B45: =$B$13/$B$26 -> 1 | D45: 1.000: an exact match.
A46: EU allowances (70% of 2025) | B46: =$B$13*'Rule tables'!$B$25 -> 262.4491 | C46: EUAs | E46: Directive Art. 3gb.
A47: EU ETS cost | B47: =$B$46*Assumptions!$B$7 -> 22308.173 | C47: €
...

Sheet CII
A1: IMO CII — the A to E rating
A2: Attained CII = CO2 ÷ (capacity × distance). It is compared with a required value that tightens every year to 2030.
A5: Part A — simple ship: bulk carrier, 50,000 DWT, 3,000 t HFO, 50,000 nm, 2026
A6: Step | B6: Value | C6: Unit | D6: How it is worked out | E6: Source
A7: Year | B7: 2026
A8: CO2 emitted in the year | B8: ='Rule tables'!$B$7*3000 -> 9342 | C8: t | D8: Fuel × carbon factor (Part B: the register's total CO2).
A9: Capacity (deadweight) | B9: 50000 | C9: DWT | D9: Bulk carriers use DWT, capped at 279,000. | E9: MEPC.352(78).
A10: Distance sailed | B10: 50000 | C10: nm | D10: Part B: the register's CO2 ÷ its CO2 per nautical mile.
A11: Attained CII | B11: =$B$8*1000000/($B$9*$B$10) -> 3.7368 | C11: gCO2 / DWT·nm | D11: CO2 in grams ÷ (capacity × distance). | E11: G1, MEPC.352(78).
A12: Reference line | B12: ='Rule tables'!$B$58*$B$9^(-'Rule tables'!$B$59) -> 5.6686139 | C12: gCO2 / DWT·nm | D12: a × capacity^(−c). | E12: G2, MEPC.353(78).
A13: Reduction factor Z | B13: =INDEX('Rule tables'!$B$70:$B$77,MATCH($B$7,'Rule tables'!$A$70:$A$77,0)) -> 0.11 | E13: G3.
A14: Required CII | B14: =$B$12*(1-$B$13) -> 5.0450663 | C14: gCO2 / DWT·nm | D14: Reference × (1 − Z).
A15: Attained ÷ required | B15: =$B$11/$B$14 -> 0.74068402
A16: Boundary A/B | B16: ='Rule tables'!$B$62*$B$14 -> 4.338757 | C16: gCO2 / DWT·nm | D16: d1 × required. | E16: G4, MEPC.354(78).
A17: Boundary B/C | B17: ='Rule tables'!$B$63*$B$14 -> 4.7423624 | C17: gCO2 / DWT·nm | D17: d2 × required. | E17: G4, MEPC.354(78).
A18: Boundary C/D | B18: ='Rule tables'!$B$64*$B$14 -> 5.3477703 | C18: gCO2 / DWT·nm | D18: d3 × required. | E18: G4, MEPC.354(78).
A19: Boundary D/E | B19: ='Rule tables'!$B$65*$B$14 -> 5.9531783 | C19: gCO2 / DWT·nm | D19: d4 × required. | E19: G4, MEPC.354(78).
A20: Rating | B20: =IF($B$15<='Rule tables'!$B$62,"A",IF($B$15<='Rule tables'!$B$63,"B",IF($B$15<='Rule tables'!$B$64,"C",IF($B$15<='Rule tables'!$B$65,"D","E")))) -> A | D20: Compare the ratio with d1 to d4.
A22: Part B — PETER OLDENDORFF, 2025, with 93,000 DWT entered
A23: Step | B23: Value | C23: Unit | D23: How it is worked out | E23: Source
A24: Year | B24: 2025
A25: CO2 emitted in the year | B25: ='EU ETS'!$B$8+'EU ETS'!$B$9+'EU ETS'!$B$10+'EU ETS'!$B$11 -> 13829.152 | C25: t | D25: Fuel × carbon factor (Part B: the register's total CO2).
A26: Capacity (deadweight) | B26: 93000 | C26: DWT | D26: Bulk carriers use DWT, capped at 279,000. | E26: MEPC.352(78).
A27: Distance sailed | B27: 32515.465 | C27: nm | D27: Part B: the register's CO2 ÷ its CO2 per nautical mile.
A28: Attained CII | B28: =$B$25*1000000/($B$26*$B$27) -> 4.5732258 | C28: gCO2 / DWT·nm | D28: CO2 in grams ÷ (capacity × distance). | E28: G1, MEPC.352(78).
A29: Reference line | B29: ='Rule tables'!$B$58*$B$26^(-'Rule tables'!$B$59) -> 3.8533621 | C29: gCO2 / DWT·nm | D29: a × capacity^(−c). | E29: G2, MEPC.353(78).
A30: Reduction factor Z | B30: =INDEX('Rule tables'!$B$70:$B$77,MATCH($B$24,'Rule tables'!$A$70:$A$77,0)) -> 0.09 | E30: G3.
A31: Required CII | B31: =$B$29*(1-$B$30) -> 3.5065595 | C31: gCO2 / DWT·nm | D31: Reference × (1 − Z).
A32: Attained ÷ required | B32: =$B$28/$B$31 -> 1.3041917
A33: Boundary A/B | B33: ='Rule tables'!$B$62*$B$31 -> 3.0156412 | C33: gCO2 / DWT·nm | D33: d1 × required. | E33: G4, MEPC.354(78).
A34: Boundary B/C | B34: ='Rule tables'!$B$63*$B$31 -> 3.2961659 | C34: gCO2 / DWT·nm | D34: d2 × required. | E34: G4, MEPC.354(78).
A35: Boundary C/D | B35: ='Rule tables'!$B$64*$B$31 -> 3.7169531 | C35: gCO2 / DWT·nm | D35: d3 × required. | E35: G4, MEPC.354(78).
A36: Boundary D/E | B36: ='Rule tables'!$B$65*$B$31 -> 4.1377402 | C36: gCO2 / DWT·nm | D36: d4 × required. | E36: G4, MEPC.354(78).
A37: Rating | B37: =IF($B$32<='Rule tables'!$B$62,"A",IF($B$32<='Rule tables'!$B$63,"B",IF($B$32<='Rule tables'!$B$64,"C",IF($B$32<='Rule tables'!$B$65,"D","E")))) -> E | D37: Compare the ratio with d1 to d4.
A39: Part C — the simple ship's rating, 2023 to 2030, at the same performance
A40: Step | B40: Value | C40: Unit | D40: How it is worked out | E40: Source
A41: 2023: rating | B41: =IF($B$11/($B$12*(1-'Rule tables'!$B$70))<='Rule tables'!$B$62,"A",IF($B$11/($B$12*(1-'Rule tables'!$B$70))<='Rule tables'!$B$63,"B",IF($B$11/($B$12*(1-'Rule tables'!$B$70))<='Rule tables'!$B$64,"C",IF($B$11/($B$12*(1-'Rule tables'!$B$70))<='Rule tables'!$B$65,"D","E")))) -> A | D41: Required tightens with Z for 2023.
A42: 2024: rating | B42: =IF($B$11/($B$12*(1-'Rule tables'!$B$71))<='Rule tables'!$B$62,"A",IF($B$11/($B$12*(1-'Rule tables'!$B$71))<='Rule tables'!$B$63,"B",IF($B$11/($B$12*(1-'Rule tables'!$B$71))<='Rule tables'!$B$64,"C",IF($B$11/($B$12*(1-'Rule tables'!$B$71))<='Rule tables'!$B$65,"D","E")))) -> A | D42: Required tightens with Z for 2024.
A43: 2025: rating | B43: =IF($B$11/($B$12*(1-'Rule tables'!$B$72))<='Rule tables'!$B$62,"A",IF($B$11/($B$12*(1-'Rule tables'!$B$72))<='Rule tables'!$B$63,"B",IF($B$11/($B$12*(1-'Rule tables'!$B$72))<='Rule tables'!$B$64,"C",IF($B$11/($B$12*(1-'Rule tables'!$B$72))<='Rule tables'!$B$65,"D","E")))) -> A | D43: Required tightens with Z for 2025.
A44: 2026: rating | B44: =IF($B$11/($B$12*(1-'Rule tables'!$B$73))<='Rule tables'!$B$62,"A",IF($B$11/($B$12*(1-'Rule tables'!$B$73))<='Rule tables'!$B$63,"B",IF($B$11/($B$12*(1-'Rule tables'!$B$73))<='Rule tables'!$B$64,"C",IF($B$11/($B$12*(1-'Rule tables'!$B$73))<='Rule tables'!$B$65,"D","E")))) -> A | D44: Required tightens with Z for 2026.
...

Sheet CII G5
A1: CII corrections — MEPC.355(78) (G5)
A2: IMO lets some fuel come out of the CII: voyage adjustments (safety, ice), and part of the fuel for reefers, cargo cooling, cargo heating and discharge pumps.
A5: Container ship, 50,000 DWT, 10,000 t HFO, 100,000 nm, 2026, reefers without kWh meters
A6: Step | B6: Value | C6: Unit | D6: How it is worked out | E6: Source
A7: Year | B7: 2026
A8: HFO burned | B8: 10000 | C8: t | E8: Example.
A9: Capacity | B9: 50000 | C9: DWT | E9: Example.
A10: Distance | B10: 100000 | C10: nm | E10: Example.
A11: In-use reefer-days (from BAPLIE files) | B11: 1000 | C11: reefer-days | E11: Example.
A12: Fuel for reefers | B12: ='Rule tables'!$B$87*24*'Rule tables'!$B$88*$B$11/1000000 -> 11.55 | C12: t | D12: 2.75 kW × 24 h × 175 g/kWh × reefer-days. | E12: G5 Appendix 1 Part A.1.2.
A13: Share of that fuel that may come out | B13: =0.75-0.03*MAX(0,$B$7-2023) -> 0.66 | D13: 0.75 − 0.03 × years since 2023: 0.66 in 2026. | E13: G5 section 4.
A14: CO2 counted in the CII | B14: ='Rule tables'!$B$7*($B$8-$B$13*$B$12) -> 31116.262 | C14: t | D14: 3.114 × (fuel − share × reefer fuel).
A15: Attained CII with the correction | B15: =$B$14*1000000/($B$9*$B$10) -> 6.2232524 | C15: gCO2 / DWT·nm
A16: Attained CII without it | B16: ='Rule tables'!$B$7*$B$8*1000000/($B$9*$B$10) -> 6.228 | C16: gCO2 / DWT·nm
A17: Required CII (container) | B17: ='Rule tables'!$B$60*$B$9^(-'Rule tables'!$B$61)*(1-INDEX('Rule tables'!$B$70:$B$77,MATCH($B$7,'Rule tables'!$A$70:$A$77,0))) -> 8.8947827
A18: Other G5 items: voyage adjustments remove both fuel and distance (MARPOL Annex VI reg. 3.1 safety situations; ice-classed ships within the ice edge). STS voyages on tankers: fuel × (1 − 6.1742 × DWT^−0.246). Shuttle tankers with DP: all fuel × (1 − 5.6805 × DWT^−0.208). Cargo cooling (gas and LNG carriers), electric discharge pumps, cargo-heating boilers and engine-driven pumps (tankers) use the same 0.75 − 0.03y share. Only figures your Administration accepts may be used.

Sheet EEXI
A1: EEXI — the design check
A2: The required EEXI is the EEDI reference line for the ship type and size, cut by a reduction factor. The attained value is what the ship filed.
A5: PETER OLDENDORFF: bulk carrier, 93,000 DWT
A6: Step | B6: Value | C6: Unit | D6: How it is worked out | E6: Source
A7: Deadweight | B7: 93000 | C7: DWT | E7: Entered by the user.
A8: EEDI reference line | B8: ='Rule tables'!$B$81*$B$7^(-'Rule tables'!$B$82) -> 4.1031169 | C8: gCO2/t·nm | D8: 961.79 × DWT^(−0.477).
A9: Required EEXI | B9: =$B$8*(1-'Rule tables'!$B$83) -> 3.2824935 | C9: gCO2/t·nm | D9: Reference × (1 − 20%).
A10: Attained EEXI, as filed | B10: 2.97 | C10: gCO2/t·nm | E10: EMSA register, 'Technical efficiency': EEXI (2.97).
A11: Margin | B11: =($B$9-$B$10)/$B$9 -> 0.095200043 | D11: Positive = below the required value.
A12: Verdict | B12: =IF($B$10<=$B$9,"COMPLIANT","ABOVE REQUIRED") -> COMPLIANT

Sheet Own data bill
A1: Your own fuel, split by voyage type
A2: When you enter your own fuel, you say where it was burned. Each share is charged by its own rule; the rest is out of scope.
A5: Bulk carrier, 4,300 t HFO, 2026
A6: Step | B6: Value | C6: Unit | D6: How it is worked out | E6: Source
A7: Year | B7: 2026
A8: HFO burned in the year | B8: 4300 | C8: t | E8: Example.
A9: Share between EU/EEA ports | B9: 0.4 | E9: Your voyage data.
A10: Share into or out of the EU/EEA | B10: 0.3 | E10: Same.
A11: Share at berth in EU/EEA ports | B11: 0.1 | E11: Same.
A12: Share on UK domestic voyages and UK berths | B12: 0.05 | E12: Same.
A13: Share Great Britain to Northern Ireland | B13: 0 | E13: Same.
A14: Outside EU and UK scope | B14: =1-$B$9-$B$10-$B$11-$B$12-$B$13 -> 0.15 | D14: Must not be negative.
A15: CO2e per tonne of HFO (with methane and N2O) | B15: ='Rule tables'!$B$7+IF($B$7>='Rule tables'!$B$19,'Rule tables'!$B$15*'Rule tables'!$B$17+'Rule tables'!$B$16*'Rule tables'!$B$18,0) -> 3.1631 | C15: t CO2e / t | D15: 3.114 + 0.00005 × 28 + 0.00018 × 265 = 3.1631.
A16: EU-scope fuel | B16: =$B$8*($B$9*'Rule tables'!$B$34+$B$10*'Rule tables'!$B$35+$B$11*'Rule tables'!$B$36) -> 2795 | C16: t | D16: 100% / 50% / 100%.
A17: EU ETS CO2e | B17: =$B$16*$B$15 -> 8840.8645 | C17: t CO2e
A18: EU ETS cost | B18: =$B$17*INDEX('Rule tables'!$B$23:$B$30,MATCH($B$7,'Rule tables'!$A$23:$A$30,0))*Assumptions!$B$7 -> 751473.48 | C18: €
A19: UK-scope fuel | B19: =$B$8*($B$12+$B$13*'Rule tables'!$B$37) -> 215 | C19: t | D19: 100% domestic, 50% GB to NI. | E19: SI 2026/392 Sch. 2A.
A20: UK ETS CO2e | B20: =$B$19*$B$15 -> 680.0665 | C20: t CO2e | D20: Methane and N2O count from the start.
A21: UK ETS cost | B21: =$B$20*Assumptions!$B$8 -> 27202.66 | C21: £
A22: UK ETS cost in euros | B22: =$B$21*Assumptions!$B$9 -> 31283.059 | C22: €
A23: FuelEU energy in scope | B23: =$B$16*'Rule tables'!$B$49 -> 113197500 | C23: MJ | D23: Same shares as the ETS.
A24: FuelEU compliance balance | B24: =('Rule tables'!$B$41*(1-INDEX('Rule tables'!$B$42:$B$48,MATCH($B$7,'Rule tables'!$A$42:$A$48,0)))-'Rule tables'!$B$50)*$B$23/1000000 -> -272.03623 | C24: t CO2e
A25: FuelEU penalty if paid | B25: =IF($B$24<0,ABS($B$24)*1000000/('Rule tables'!$B$50*'Rule tables'!$B$54)*'Rule tables'!$B$53*(1+(Assumptions!$B$11-1)/10),0) -> 173578.29 | C25: €
A26: FuelEU if pooled | B26: =IF($B$24<0,ABS($B$24)*Assumptions!$B$10,0) -> 29923.986 | C26: €
A27: Total bill, FuelEU at the penalty | B27: =$B$18+$B$22+$B$25 -> 956334.83 | C27: €
A28: Total bill, FuelEU pooled | B28: =$B$18+$B$22+$B$26 -> 812680.53 | C28: €

Sheet Charter split
A1: Owner and time-charterer split
A2: BIMCO's ETS (2022) and FuelEU (2024) time-charter clauses put the cost of emissions during the charter on the charterer. Without voyage data, split by days.
A5: Charter 1 March to 31 August 2025, EU ETS cost €100,000
A6: Step | B6: Value | C6: Unit | D6: How it is worked out | E6: Source
A7: Year | B7: 2025
A8: Charter from | B8: =DATE(2025,3,1) -> 45717 | E8: Charter party.
A9: Charter to | B9: =DATE(2025,8,31) -> 45900 | E9: Charter party.
A10: Cost to split | B10: 100000 | C10: € | E10: Example.
A11: Days on charter in the year | B11: =MAX(0,MIN($B$9,DATE($B$7,12,31))-MAX($B$8,DATE($B$7,1,1))+1) -> 184 | C11: days | D11: Both dates count.
A12: Days in the year | B12: =DATE($B$7+1,1,1)-DATE($B$7,1,1) -> 365 | C12: days
A13: Charterer share | B13: =$B$11/$B$12 -> 0.50410959
A14: Charterer pays | B14: =ROUND($B$10*$B$13,0) -> 50411 | C14: €
A15: Owner pays | B15: =$B$10-$B$14 -> 49589 | C15: €
A16: The clauses allocate the emissions actually reported for the charter period. Use those figures for the contractual statement when you have them.

Sheet What-if
A1: What-if — speed and biofuel
A2: A scenario, not a measurement. Distance stays the same; berth fuel does not change with sea speed.
A5: Slowing down
A6: Step | B6: Value | C6: Unit | D6: How it is worked out | E6: Source
A7: Speed change | B7: -0.1 | E7: Your scenario.
A8: Speed exponent n | B8: 3 | D8: Main-engine power ∝ speed^n; 3 is the cube law. | E8: Ship's speed-power curve.
A9: Auxiliaries and boilers, share of sea fuel | B9: 0 | E9: Your noon reports.
A10: Main-engine fuel per mile, ratio | B10: =(1+$B$7)^($B$8-1) -> 0.81 | D10: speed^(n−1) on the same distance.
A11: Auxiliary fuel, ratio | B11: =1/(1+$B$7) -> 1.1111111 | D11: Burns per day; the voyage takes longer.
A12: Sea fuel, ratio | B12: =(1-$B$9)*$B$10+$B$9*$B$11 -> 0.81
A14: Biofuel
A15: Step | B15: Value | C15: Unit | D15: How it is worked out | E15: Source
A16: Share of fossil energy replaced by B100 | B16: 0.2 | E16: Your scenario.
A17: HFO before | B17: 1000 | C17: t | E17: Example.
A18: Lower calorific value, B100 | B18: 37000 | C18: MJ per tonne | E18: Annex II (UCOME default).
A19: HFO after | B19: =$B$17*(1-$B$16) -> 800 | C19: t
A20: B100 needed for the same energy | B20: =$B$17*$B$16*'Rule tables'!$B$49/$B$18 -> 218.91892 | C20: t | D20: More tonnes, because B100 carries less energy per tonne.

Sheet IMO NZF
A1: IMO Net-Zero Framework — scenario only
A2: Not adopted. The IMO postponed the decision in October 2025. Shown to size the risk from 2028.
A5: Simple ship: 3,000 t HFO, scenario year 2028
A6: Step | B6: Value | C6: Unit | D6: How it is worked out | E6: Source
A7: HFO burned (all voyages count) | B7: 3000 | C7: t | E7: Example.
A8: Energy | B8: =$B$7*'Rule tables'!$B$49 -> 121500000 | C8: MJ
A9: GHG fuel intensity | B9: ='Rule tables'!$B$50 -> 91.74 | C9: gCO2e/MJ
A10: Base target | B10: ='Rule tables'!$B$92*(1-'Rule tables'!$B$93) -> 89.568 | C10: gCO2e/MJ
A11: Direct compliance target | B11: ='Rule tables'!$B$92*(1-'Rule tables'!$B$94) -> 77.439 | C11: gCO2e/MJ
A12: Tier 2 deficit (above the base target) | B12: =MAX(0,$B$9-$B$10)*$B$8/1000000 -> 263.898 | C12: t CO2e
A13: Tier 1 deficit (between the targets) | B13: =(MIN($B$9,$B$10)-$B$11)*$B$8/1000000*($B$9>$B$11) -> 1473.6735 | C13: t CO2e
A14: Remedial units | B14: =$B$13*'Rule tables'!$B$95+$B$12*'Rule tables'!$B$96 -> 247648.59 | C14: $

Sheet Ship check
A1: Check any ship
A2: Copy a ship's register figures from the Verifier view on carbonkeel.com into the yellow cells. The bill is worked out with the same rules; the fuel mix comes from the register's CO2 ÷ fuel.
A5: Your ship (example: PETER OLDENDORFF)
A6: Step | B6: Value | C6: Unit | D6: How it is worked out | E6: Source
A7: Emissions year | B7: 2025
A8: CO2 between EU/EEA ports | B8: 602.76325 | C8: t | E8: Register.
A9: CO2 leaving an EU/EEA port | B9: 5346.6826 | C9: t | E9: Register.
A10: CO2 arriving at an EU/EEA port | B10: 7493.6838 | C10: t | E10: Register.
A11: CO2 at berth in EU/EEA ports | B11: 386.02269 | C11: t | E11: Register.
A12: Verifier-reported ETS-scope CO2 (blank if none) | B12: 7408.9691 | C12: t | E12: Register.
A13: Our rebuild | B13: =$B$8+0.5*($B$9+$B$10)+$B$11 -> 7408.9691 | C13: t
A14: CO2 the bill uses | B14: =IF($B$12="",$B$13,$B$12) -> 7408.9691 | C14: t | D14: The verifier's figure when there is one.
A15: EU ETS cost | B15: =$B$14*INDEX('Rule tables'!$B$23:$B$30,MATCH($B$7,'Rule tables'!$A$23:$A$30,0))*Assumptions!$B$7 -> 440833.66 | C15: €
A16: Total CO2 in the year | B16: 13829.152 | C16: t | E16: Register.
A17: Total fuel in the year | B17: 4426.558 | C17: t | E17: Register.
A18: Gas oil share of the fuel | B18: =MAX(0,MIN(1,($B$16/$B$17-'Rule tables'!$B$7)/('Rule tables'!$B$9-'Rule tables'!$B$7))) -> 0.1101325 | D18: From CO2 ÷ fuel, as on the FuelEU tab.
A19: Fuel in scope | B19: =$B$13/($B$16/$B$17) -> 2371.5287 | C19: t
A20: Energy in scope | B20: =$B$19*((1-$B$18)*'Rule tables'!$B$49+$B$18*'Rule tables'!$B$51) -> 96621513 | C20: MJ
A21: GHG intensity | B21: =$B$19*((1-$B$18)*'Rule tables'!$B$49*'Rule tables'!$B$50+$B$18*'Rule tables'!$B$51*'Rule tables'!$B$52)/$B$20 -> 91.628038 | C21: gCO2e/MJ
A22: FuelEU balance | B22: =IF($B$14=0,0,('Rule tables'!$B$41*(1-INDEX('Rule tables'!$B$42:$B$48,MATCH(MAX(2025,$B$7),'Rule tables'!$A$42:$A$48,0)))-$B$21)*$B$20/1000000) -> -221.38291 | C22: t CO2e | D22: No FuelEU before 2025, or when the verifier reported no ETS-scope CO2.
A23: FuelEU penalty if paid | B23: =IF(OR($B$7<2025,$B$22>=0),0,ABS($B$22)*1000000/($B$21*'Rule tables'!$B$54)*'Rule tables'!$B$53*(1+(Assumptions!$B$11-1)/10)) -> 141430.5 | C23: €
A24: FuelEU if pooled | B24: =IF(OR($B$7<2025,$B$22>=0),0,ABS($B$22)*Assumptions!$B$10) -> 24352.12 | C24: €
A25: Total, FuelEU at the penalty | B25: =$B$15+$B$23 -> 582264.17 | C25: €

Sheet Cross-check
A1: Cross-check — workbook against the CarbonKeel engine
A2: Each row compares a result worked out in this workbook with the figure CarbonKeel's engine produced on 17 October 2026 with the default assumptions. If you change an assumption, the engine column no longer applies and a FAIL is expected. The engine rounds its outputs, hence the allowed difference.
A5: Numbers
A6: Check | B6: This workbook | C6: CarbonKeel engine | D6: Difference | E6: Allowed | F6: Result
A7: EU ETS: PETER OLDENDORFF rebuild | B7: ='EU ETS'!$B$16 -> 7408.9691 | C7: 7409 | D7: =B7-C7 -> -0.03086 | E7: 0.1 | F7: =IF(ABS(D7)<=E7+0.5*10^-6*ABS(C7),"PASS","FAIL") -> PASS
A8: EU ETS: PETER OLDENDORFF allowances | B8: ='EU ETS'!$B$20 -> 5186.2784 | C8: 5186.3 | D8: =B8-C8 -> -0.021602 | E8: 0.1 | F8: =IF(ABS(D8)<=E8+0.5*10^-6*ABS(C8),"PASS","FAIL") -> PASS
A9: EU ETS: PETER OLDENDORFF cost (€) | B9: ='EU ETS'!$B$21 -> 440833.66 | C9: 440834 | D9: =B9-C9 -> -0.33617 | E9: 1 | F9: =IF(ABS(D9)<=E9+0.5*10^-6*ABS(C9),"PASS","FAIL") -> PASS
A10: EU ETS: simple ship CO2e (t) | B10: ='EU ETS'!$B$31 -> 9489.3 | C10: 9489.3 | D10: =B10-C10 -> 0 | E10: 0.1 | F10: =IF(ABS(D10)<=E10+0.5*10^-6*ABS(C10),"PASS","FAIL") -> PASS
A11: EU ETS: simple ship cost (€) | B11: ='EU ETS'!$B$34 -> 806590.5 | C11: 806590 | D11: =B11-C11 -> 0.5 | E11: 1 | F11: =IF(ABS(D11)<=E11+0.5*10^-6*ABS(C11),"PASS","FAIL") -> PASS
A12: FuelEU: simple ship energy (MJ) | B12: =FuelEU!$B$16 -> 121500000 | C12: 121500000 | D12: =B12-C12 -> 0 | E12: 1 | F12: =IF(ABS(D12)<=E12+0.5*10^-6*ABS(C12),"PASS","FAIL") -> PASS
A13: FuelEU: simple ship balance (t) | B13: =FuelEU!$B$22 -> -291.9888 | C13: -292 | D13: =B13-C13 -> 0.0112 | E13: 0.1 | F13: =IF(ABS(D13)<=E13+0.5*10^-6*ABS(C13),"PASS","FAIL") -> PASS
A14: FuelEU: simple ship penalty (€) | B14: =FuelEU!$B$25 -> 186309.43 | C14: 186309 | D14: =B14-C14 -> 0.43227679 | E14: 1 | F14: =IF(ABS(D14)<=E14+0.5*10^-6*ABS(C14),"PASS","FAIL") -> PASS
A15: FuelEU: simple ship pooled (€) | B15: =FuelEU!$B$26 -> 32118.768 | C15: 32119 | D15: =B15-C15 -> -0.232 | E15: 1 | F15: =IF(ABS(D15)<=E15+0.5*10^-6*ABS(C15),"PASS","FAIL") -> PASS
A16: FuelEU: statutory € per tCO2e | B16: =FuelEU!$B$23 -> 638.07047 | C16: 638.07 | D16: =B16-C16 -> 0.00047488395 | E16: 0.01 | F16: =IF(ABS(D16)<=E16+0.5*10^-6*ABS(C16),"PASS","FAIL") -> PASS
A17: FuelEU: PETER OLDENDORFF energy (MJ) | B17: =FuelEU!$B$40 -> 96621513 | C17: 96621513 | D17: =B17-C17 -> 0.45779112 | E17: 1 | F17: =IF(ABS(D17)<=E17+0.5*10^-6*ABS(C17),"PASS","FAIL") -> PASS
A18: FuelEU: PETER OLDENDORFF balance (t) | B18: =FuelEU!$B$46 -> -221.38291 | C18: -221.4 | D18: =B18-C18 -> 0.01709234 | E18: 0.1 | F18: =IF(ABS(D18)<=E18+0.5*10^-6*ABS(C18),"PASS","FAIL") -> PASS
A19: FuelEU: PETER OLDENDORFF penalty (€) | B19: =FuelEU!$B$49 -> 141430.5 | C19: 141431 | D19: =B19-C19 -> -0.49772223 | E19: 1 | F19: =IF(ABS(D19)<=E19+0.5*10^-6*ABS(C19),"PASS","FAIL") -> PASS
A20: FuelEU: PETER OLDENDORFF pooled (€) | B20: =FuelEU!$B$50 -> 24352.12 | C20: 24352 | D20: =B20-C20 -> 0.11984263 | E20: 1 | F20: =IF(ABS(D20)<=E20+0.5*10^-6*ABS(C20),"PASS","FAIL") -> PASS
A21: CII: simple ship attained | B21: =CII!$B$11 -> 3.7368 | C21: 3.737 | D21: =B21-C21 -> -0.0002 | E21: 0.0005 | F21: =IF(ABS(D21)<=E21+0.5*10^-6*ABS(C21),"PASS","FAIL") -> PASS
A22: CII: simple ship required | B22: =CII!$B$14 -> 5.0450663 | C22: 5.045 | D22: =B22-C22 -> 6.6332496e-05 | E22: 0.0005 | F22: =IF(ABS(D22)<=E22+0.5*10^-6*ABS(C22),"PASS","FAIL") -> PASS
A23: CII: PETER OLDENDORFF attained | B23: =CII!$B$28 -> 4.5732258 | C23: 4.573 | D23: =B23-C23 -> 0.00022580645 | E23: 0.0005 | F23: =IF(ABS(D23)<=E23+0.5*10^-6*ABS(C23),"PASS","FAIL") -> PASS
A24: CII: PETER OLDENDORFF required | B24: =CII!$B$31 -> 3.5065595 | C24: 3.507 | D24: =B24-C24 -> -0.00044047908 | E24: 0.0005 | F24: =IF(ABS(D24)<=E24+0.5*10^-6*ABS(C24),"PASS","FAIL") -> PASS
A25: CII G5: reefer-corrected attained | B25: ='CII G5'!$B$15 -> 6.2232524 | C25: 6.223 | D25: =B25-C25 -> 0.0002523956 | E25: 0.0005 | F25: =IF(ABS(D25)<=E25+0.5*10^-6*ABS(C25),"PASS","FAIL") -> PASS
A26: CII G5: container required | B26: ='CII G5'!$B$17 -> 8.8947827 | C26: 8.895 | D26: =B26-C26 -> -0.00021730758 | E26: 0.0005 | F26: =IF(ABS(D26)<=E26+0.5*10^-6*ABS(C26),"PASS","FAIL") -> PASS
A27: EEXI: required | B27: =EEXI!$B$9 -> 3.2824935 | C27: 3.28 | D27: =B27-C27 -> 0.002493523 | E27: 0.005 | F27: =IF(ABS(D27)<=E27+0.5*10^-6*ABS(C27),"PASS","FAIL") -> PASS
A28: Own data: EU ETS CO2e (t) | B28: ='Own data bill'!$B$17 -> 8840.8645 | C28: 8840.9 | D28: =B28-C28 -> -0.0355 | E28: 0.1 | F28: =IF(ABS(D28)<=E28+0.5*10^-6*ABS(C28),"PASS","FAIL") -> PASS
A29: Own data: EU ETS cost (€) | B29: ='Own data bill'!$B$18 -> 751473.48 | C29: 751473 | D29: =B29-C29 -> 0.4825 | E29: 1 | F29: =IF(ABS(D29)<=E29+0.5*10^-6*ABS(C29),"PASS","FAIL") -> PASS
A30: Own data: UK ETS cost (£) | B30: ='Own data bill'!$B$21 -> 27202.66 | C30: 27203 | D30: =B30-C30 -> -0.34 | E30: 1 | F30: =IF(ABS(D30)<=E30+0.5*10^-6*ABS(C30),"PASS","FAIL") -> PASS
A31: Own data: FuelEU balance (t) | B31: ='Own data bill'!$B$24 -> -272.03623 | C31: -272 | D31: =B31-C31 -> -0.036232 | E31: 0.1 | F31: =IF(ABS(D31)<=E31+0.5*10^-6*ABS(C31),"PASS","FAIL") -> PASS
A32: Own data: FuelEU penalty (€) | B32: ='Own data bill'!$B$25 -> 173578.29 | C32: 173578 | D32: =B32-C32 -> 0.28773788 | E32: 1 | F32: =IF(ABS(D32)<=E32+0.5*10^-6*ABS(C32),"PASS","FAIL") -> PASS
A33: Own data: FuelEU pooled (€) | B33: ='Own data bill'!$B$26 -> 29923.986 | C33: 29924 | D33: =B33-C33 -> -0.01448 | E33: 1 | F33: =IF(ABS(D33)<=E33+0.5*10^-6*ABS(C33),"PASS","FAIL") -> PASS
A34: Charter: days on charter | B34: ='Charter split'!$B$11 -> 184 | C34: 184 | D34: =B34-C34 -> 0 | E34: 0 | F34: =IF(ABS(D34)<=E34+0.5*10^-6*ABS(C34),"PASS","FAIL") -> PASS
A35: Charter: charterer pays (€) | B35: ='Charter split'!$B$14 -> 50411 | C35: 50411 | D35: =B35-C35 -> 0 | E35: 0 | F35: =IF(ABS(D35)<=E35+0.5*10^-6*ABS(C35),"PASS","FAIL") -> PASS
A36: What-if: sea fuel ratio, −10%, cube law | B36: ='What-if'!$B$12 -> 0.81 | C36: 0.81 | D36: =B36-C36 -> 0 | E36: 0.0001 | F36: =IF(ABS(D36)<=E36+0.5*10^-6*ABS(C36),"PASS","FAIL") -> PASS
A37: IMO NZF: remedial units ($) | B37: ='IMO NZF'!$B$14 -> 247648.59 | C37: 247649 | D37: =B37-C37 -> -0.41 | E37: 5 | F37: =IF(ABS(D37)<=E37+0.5*10^-6*ABS(C37),"PASS","FAIL") -> PASS
A38: Ship check: EU ETS cost (€) | B38: ='Ship check'!$B$15 -> 440833.66 | C38: 440834 | D38: =B38-C38 -> -0.33617 | E38: 1 | F38: =IF(ABS(D38)<=E38+0.5*10^-6*ABS(C38),"PASS","FAIL") -> PASS
A39: Ship check: FuelEU penalty (€) | B39: ='Ship check'!$B$23 -> 141430.5 | C39: 141431 | D39: =B39-C39 -> -0.49772223 | E39: 1 | F39: =IF(ABS(D39)<=E39+0.5*10^-6*ABS(C39),"PASS","FAIL") -> PASS
A40: FuelEU: PETER OLDENDORFF intensity | B40: =FuelEU!$B$42 -> 91.628038 | C40: 91.63 | D40: =B40-C40 -> -0.0019617474 | E40: 0.005 | F40: =IF(ABS(D40)<=E40+0.5*10^-6*ABS(C40),"PASS","FAIL") -> PASS
A41: COOL MAGNUS: CO2 in scope (t) | B41: ='COOL MAGNUS'!$B$26 -> 374.92727 | C41: 374.9 | D41: =B41-C41 -> 0.027275 | E41: 0.1 | F41: =IF(ABS(D41)<=E41+0.5*10^-6*ABS(C41),"PASS","FAIL") -> PASS
A42: COOL MAGNUS: FuelEU energy (MJ) | B42: ='COOL MAGNUS'!$B$31 -> 4993572.9 | C42: 4993573 | D42: =B42-C42 -> -0.13680583 | E42: 1 | F42: =IF(ABS(D42)<=E42+0.5*10^-6*ABS(C42),"PASS","FAIL") -> PASS
...
